Workbook
Name Tiendas: 'Tiendas operando '!$B:$B

Sheet MS26
A1: # Microsaturación | B1: Fecha recepción | C1: Fecha de envío | D1: Días de envío | E1: Practicante | F1: Region | G1: UPZ | H1: Nombre PP | I1: Estado | J1: Especialista | K1: Longitud | L1: Latitud | M1: Tienda Microsaturada 1 | N1: Riesgo | O1: Tienda Microsaturada 2 | P1: Riesgo | Q1: Tipo de estudio | R1: Tienda Microsaturada 3 | S1: Riesgo | T1: Tipo de estudio | U1: Tienda Microsaturada 4 | V1: Riesgo | W1: Tipo de estudio | X1: Tienda Microsaturada 5 | Y1: Riesgo | Z1: Tipo de estudio | AA1: Tienda Microsaturada 6 | AB1: Riesgo | AC1: Tipo de estudio | AD1: Tiendas evaluadas | AE1: Ubicación
A2: 1 | B2: 45853 | F2: Bogotá | G2: Los Cedros | H2: Country 134 | I2: Entregado | J2: Maria Alejandra Ardila Sanchez | K2: -74.047726 | L2: 4.7184032 | M2: Contador (Bog) | N2: Medio | AD2: =COUNTA(M2,O2,R2,U2,X2,AA2) -> 1 | AE2: =+HYPERLINK("https://www.google.com/maps?q=" & SUBSTITUTE(L2, ",", ".") & "," & SUBSTITUTE(K2, ",", "."),"Ver en mapa") -> Ver en mapa
A3: 2 | B3: 45853 | F3: Bogotá | G3: Los Alcazares | H3: Balcones Polo | I3: Entregado | J3: Maria Alejandra Ardila Sanchez | K3: -74.067613 | L3: 4.6743335 | AD3: =COUNTA(M3,O3,R3,U3,X3,AA3) -> 0 | AE3: =+HYPERLINK("https://www.google.com/maps?q=" & SUBSTITUTE(L3, ",", ".") & "," & SUBSTITUTE(K3, ",", "."),"Ver en mapa") -> Ver en mapa
A4: 3 | B4: 45853 | F4: Bogotá | G4: Chico Lago | H4: WTC | I4: Entregado | J4: Martha Lopez | K4: -74.040866 | L4: 4.6812406 | M4: Capital Towers Bog | N4: Medio | O4: Trade Center Bog | P4: Medio | AD4: =COUNTA(M4,O4,R4,U4,X4,AA4) -> 2 | AE4: =+HYPERLINK("https://www.google.com/maps?q=" & SUBSTITUTE(L4, ",", ".") & "," & SUBSTITUTE(K4, ",", "."),"Ver en mapa") -> Ver en mapa
A5: 4 | B5: 45854 | F5: Bogotá | G5: Galerias | H5: Caracas 49 | I5: Entregado | J5: Jenny Paola Acuña Rojas | K5: -74.067101 | L5: 4.637134 | M5: Alfonso Lopez (Bog) | N5: Alto | O5: Quesada 52 Bog | P5: Medio | AD5: =COUNTA(M5,O5,R5,U5,X5,AA5) -> 2 | AE5: =+HYPERLINK("https://www.google.com/maps?q=" & SUBSTITUTE(L5, ",", ".") & "," & SUBSTITUTE(K5, ",", "."),"Ver en mapa") -> Ver en mapa
A6: 5 | B6: 45854 | F6: Bogotá | G6: Quinta Paredes | H6: Takay | I6: Entregado | J6: Jairo Delagado Pineda | K6: -74.083566 | L6: 4.6294916 | M6: Paseo Gran America B | N6: Alto | AD6: =COUNTA(M6,O6,R6,U6,X6,AA6) -> 1 | AE6: =+HYPERLINK("https://www.google.com/maps?q=" & SUBSTITUTE(L6, ",", ".") & "," & SUBSTITUTE(K6, ",", "."),"Ver en mapa") -> Ver en mapa
A7: 6 | B7: 45854 | F7: Bogotá | G7: Santa Cecilia | H7: NN | I7: Entregado | J7: Leidy Viviana Mejia | K7: -74.105436 | L7: 4.672036 | M7: Nromandia 53 (Bog) | N7: Alto | AD7: =COUNTA(M7,O7,R7,U7,X7,AA7) -> 1 | AE7: =+HYPERLINK("https://www.google.com/maps?q=" & SUBSTITUTE(L7, ",", ".") & "," & SUBSTITUTE(K7, ",", "."),"Ver en mapa") -> Ver en mapa
A8: 7 | B8: 45854 | F8: Bogotá | G8: Puente Aranda | H8: Américas Factory | I8: Entregado | J8: Jury Carolina Gonzalez | K8: -74.118328 | L8: 4.6301671 | AD8: =COUNTA(M8,O8,R8,U8,X8,AA8) -> 0 | AE8: =+HYPERLINK("https://www.google.com/maps?q=" & SUBSTITUTE(L8, ",", ".") & "," & SUBSTITUTE(K8, ",", "."),"Ver en mapa") -> Ver en mapa
A9: 8 | B9: 45854 | F9: Bogotá | G9: Chico Lago | H9: Bello Horizonte | I9: Entregado | J9: Jury Carolina Gonzalez | K9: -74.045009 | L9: 4.6795514 | AD9: =COUNTA(M9,O9,R9,U9,X9,AA9) -> 0 | AE9: =+HYPERLINK("https://www.google.com/maps?q=" & SUBSTITUTE(L9, ",", ".") & "," & SUBSTITUTE(K9, ",", "."),"Ver en mapa") -> Ver en mapa
A10: 9 | B10: 45855 | F10: Bogotá | G10: Chapinero | H10: Latitud 58 | I10: Entregado | J10: Jairo Ernesto Castilla | K10: -74.064278 | L10: 4.6449321 | M10: calle 59 Bog | N10: Alto | O10: Infinitum Bog | P10: Alto | AD10: =COUNTA(M10,O10,R10,U10,X10,AA10) -> 2 | AE10: =+HYPERLINK("https://www.google.com/maps?q=" & SUBSTITUTE(L10, ",", ".") & "," & SUBSTITUTE(K10, ",", "."),"Ver en mapa") -> Ver en mapa
A11: 10 | B11: 45855 | F11: Bogotá | G11: Chico Lago | H11: Central 75 | I11: Entregado | J11: Jairo Ernesto Castilla | K11: -74.059604 | L11: 4.6621633 | AD11: =COUNTA(M11,O11,R11,U11,X11,AA11) -> 0 | AE11: =+HYPERLINK("https://www.google.com/maps?q=" & SUBSTITUTE(L11, ",", ".") & "," & SUBSTITUTE(K11, ",", "."),"Ver en mapa") -> Ver en mapa
A12: 11 | B12: 45855 | F12: Bogotá | G12: Chico Lago | H12: Lago Cra 13 | I12: Entregado | J12: Jairo Ernesto Castilla | K12: -74.056398 | L12: 4.6643792 | M12: Calle 77 Bog | N12: Alto | O12: Lago Gaitan Bog | P12: Bajo | R12: Unilago Bog | S12: Medio | AD12: =COUNTA(M12,O12,R12,U12,X12,AA12) -> 3 | AE12: =+HYPERLINK("https://www.google.com/maps?q=" & SUBSTITUTE(L12, ",", ".") & "," & SUBSTITUTE(K12, ",", "."),"Ver en mapa") -> Ver en mapa
A13: 12 | B13: 45855 | F13: Bogotá | G13: Chico Lago | H13: Cabrera 85 | I13: Entregado | J13: Jairo Ernesto Castilla | K13: -74.051981 | L13: 4.668065 | M13: El Retiro | N13: Bajo | AD13: =COUNTA(M13,O13,R13,U13,X13,AA13) -> 1 | AE13: =+HYPERLINK("https://www.google.com/maps?q=" & SUBSTITUTE(L13, ",", ".") & "," & SUBSTITUTE(K13, ",", "."),"Ver en mapa") -> Ver en mapa
A14: 13 | B14: 45855 | F14: Bogotá | G14: El Refugio | H14: Escalar Nogal | I14: Entregado | J14: Jairo Ernesto Castilla | K14: -74.052025 | L14: 4.6635939 | AD14: =COUNTA(M14,O14,R14,U14,X14,AA14) -> 0 | AE14: =+HYPERLINK("https://www.google.com/maps?q=" & SUBSTITUTE(L14, ",", ".") & "," & SUBSTITUTE(K14, ",", "."),"Ver en mapa") -> Ver en mapa
A15: 14 | B15: 45855 | F15: Bogotá | G15: Chico Lago | H15: Arboledas | I15: Entregado | J15: Jairo Ernesto Castilla | K15: -74.060181 | L15: 4.6613361 | M15: Calle 77 Bog | N15: Bajo | O15: Heroes Bog | P15: Alto | AD15: =COUNTA(M15,O15,R15,U15,X15,AA15) -> 2 | AE15: =+HYPERLINK("https://www.google.com/maps?q=" & SUBSTITUTE(L15, ",", ".") & "," & SUBSTITUTE(K15, ",", "."),"Ver en mapa") -> Ver en mapa
A16: 15 | B16: 45855 | F16: Bogotá | G16: Chico Lago | H16: Estación San Felipe | I16: Entregado | J16: Jairo Ernesto Castilla | K16: -74.060806 | L16: 4.661255 | M16: Calle 77 Bog | N16: Bajo | O16: Heroes Bog | P16: Alto | AD16: =COUNTA(M16,O16,R16,U16,X16,AA16) -> 2 | AE16: =+HYPERLINK("https://www.google.com/maps?q=" & SUBSTITUTE(L16, ",", ".") & "," & SUBSTITUTE(K16, ",", "."),"Ver en mapa") -> Ver en mapa
A17: 16 | B17: 45859 | F17: Bogotá | G17: La Esmeralda | H17: Federman 50 | I17: Entregado | J17: Jenny Paola Acuña Rojas | K17: -74.084401 | L17: 4.6512898 | M17: Federman Bog | N17: Bajo | AD17: =COUNTA(M17,O17,R17,U17,X17,AA17) -> 1 | AE17: =+HYPERLINK("https://www.google.com/maps?q=" & SUBSTITUTE(L17, ",", ".") & "," & SUBSTITUTE(K17, ",", "."),"Ver en mapa") -> Ver en mapa
A18: 17 | B18: 45859 | F18: Bogotá | G18: Toberin | H18: Toberin 168 | I18: Entregado | J18: Jairo Ernesto Castilla | K18: -74.042576 | L18: 4.748259 | M18: Toberin Centro Bog | N18: Bajo | AD18: =COUNTA(M18,O18,R18,U18,X18,AA18) -> 1 | AE18: =+HYPERLINK("https://www.google.com/maps?q=" & SUBSTITUTE(L18, ",", ".") & "," & SUBSTITUTE(K18, ",", "."),"Ver en mapa") -> Ver en mapa
A19: 18 | B19: 21 | F19: Bogotá | G19: Las Nieves | H19: Nieves 22 | I19: Entregado | J19: Lina María Díaz | K19: -74.070383 | L19: 4.608782 | AD19: =COUNTA(M19,O19,R19,U19,X19,AA19) -> 0 | AE19: =+HYPERLINK("https://www.google.com/maps?q=" & SUBSTITUTE(L19, ",", ".") & "," & SUBSTITUTE(K19, ",", "."),"Ver en mapa") -> Ver en mapa
A20: 19 | B20: 45860 | F20: Bogotá | G20: Chico Lago | H20: Montecarlo | I20: Entregado | J20: Jairo Ernesto Castilla | K20: -74.045889 | L20: 4.6777222 | M20: Calle 93 Bog | N20: Bajo | O20: Calle 95 | P20: Bajo | AD20: =COUNTA(M20,O20,R20,U20,X20,AA20) -> 2 | AE20: =+HYPERLINK("https://www.google.com/maps?q=" & SUBSTITUTE(L20, ",", ".") & "," & SUBSTITUTE(K20, ",", "."),"Ver en mapa") -> Ver en mapa
A21: 20 | B21: 45860 | F21: Bogotá | G21: San Rafael | H21: Troncal Americas | I21: Entregado | J21: Jenny Paola Acuña Rojas | K21: -74.1163 | L21: 4.627688 | M21: Rotonda 60 Bog | N21: Medio | AD21: =COUNTA(M21,O21,R21,U21,X21,AA21) -> 1 | AE21: =+HYPERLINK("https://www.google.com/maps?q=" & SUBSTITUTE(L21, ",", ".") & "," & SUBSTITUTE(K21, ",", "."),"Ver en mapa") -> Ver en mapa
A22: 21 | B22: 45862 | F22: Bogotá | G22: Bolivia | H22: Montenegro | I22: Entregado | J22: Alba Yaneth Villamizar | K22: -74.115678 | L22: 4.7175681 | AD22: =COUNTA(M22,O22,R22,U22,X22,AA22) -> 0 | AE22: =+HYPERLINK("https://www.google.com/maps?q=" & SUBSTITUTE(L22, ",", ".") & "," & SUBSTITUTE(K22, ",", "."),"Ver en mapa") -> Ver en mapa
A23: 22 | B23: 45862 | F23: Bogotá | G23: La Candelaria | H23: Periodistas | I23: Revisión | J23: Jenny Paola Acuña Rojas | K23: -74.070322 | L23: 4.600592 | M23: Eje Ambiental Bog | N23: Bajo | O23: Museo Del Oro (Bog) | P23: Bajo | R23: Procuraduria Bog | S23: Bajo | AD23: =COUNTA(M23,O23,R23,U23,X23,AA23) -> 3 | AE23: =+HYPERLINK("https://www.google.com/maps?q=" & SUBSTITUTE(L23, ",", ".") & "," & SUBSTITUTE(K23, ",", "."),"Ver en mapa") -> Ver en mapa
A24: 23 | B24: 45867 | F24: Bogotá | G24: Chico Lago | H24: Nueve Cuatro | I24: Entregado | J24: Jairo Ernesto Castilla | K24: -74.046385 | L24: 4.6787098 | M24: Calle 95 | N24: Bajo | AD24: =COUNTA(M24,O24,R24,U24,X24,AA24) -> 1 | AE24: =+HYPERLINK("https://www.google.com/maps?q=" & SUBSTITUTE(L24, ",", ".") & "," & SUBSTITUTE(K24, ",", "."),"Ver en mapa") -> Ver en mapa
A25: 24 | B25: 45867 | F25: Bogotá | G25: Sagrado Corazon | H25: Museo Nacional | I25: Entregado | J25: Lina María Díaz | K25: -74.069864 | L25: 4.6138368 | M25: Decima San Diego Bog | N25: Bajo | AD25: =COUNTA(M25,O25,R25,U25,X25,AA25) -> 1 | AE25: =+HYPERLINK("https://www.google.com/maps?q=" & SUBSTITUTE(L25, ",", ".") & "," & SUBSTITUTE(K25, ",", "."),"Ver en mapa") -> Ver en mapa
A26: 25 | B26: 45868 | F26: Bogotá | G26: San Jose de Bavaria | H26: Portal Norte | I26: Entregado | J26: Alba Yaneth Villamizar | K26: -74.046594 | L26: 4.755029 | M26: Baviera 174 Bog | N26: Alto | AD26: =COUNTA(M26,O26,R26,U26,X26,AA26) -> 1 | AE26: =+HYPERLINK("https://www.google.com/maps?q=" & SUBSTITUTE(L26, ",", ".") & "," & SUBSTITUTE(K26, ",", "."),"Ver en mapa") -> Ver en mapa
A27: 26 | B27: 45873 | F27: Bogotá | G27: Galerias | H27: Chapinero Occidental | I27: Entregado | J27: Jenny Paola Acuña Rojas | K27: -74.068567 | L27: 4.6421875 | M27: Quesada 52 Bog | N27: Alto | O27: Palmas Bog | P27: Medio | AD27: =COUNTA(M27,O27,R27,U27,X27,AA27) -> 2 | AE27: =+HYPERLINK("https://www.google.com/maps?q=" & SUBSTITUTE(L27, ",", ".") & "," & SUBSTITUTE(K27, ",", "."),"Ver en mapa") -> Ver en mapa
A28: 27 | B28: 45873 | F28: Bogotá | G28: Galerias | H28: Galerias 27 | I28: Entregado | J28: Jenny Paola Acuña Rojas | K28: -74.075977 | L28: 4.6418017 | M28: Galerias 28 Bog | N28: Alto | O28: Galerias 53 Bog | P28: Alto | AD28: =COUNTA(M28,O28,R28,U28,X28,AA28) -> 2 | AE28: =+HYPERLINK("https://www.google.com/maps?q=" & SUBSTITUTE(L28, ",", ".") & "," & SUBSTITUTE(K28, ",", "."),"Ver en mapa") -> Ver en mapa
A29: 28 | B29: 45873 | F29: Bogotá | G29: Toberin | H29: 161 Express | I29: Entregado | J29: Jairo Ernesto Castilla | K29: -74.043877 | L29: 4.7410174 | M29: Estrella Norte Bog | N29: Alto | O29: Jardines del Oriente | P29: Alto | AD29: =COUNTA(M29,O29,R29,U29,X29,AA29) -> 2 | AE29: =+HYPERLINK("https://www.google.com/maps?q=" & SUBSTITUTE(L29, ",", ".") & "," & SUBSTITUTE(K29, ",", "."),"Ver en mapa") -> Ver en mapa
A30: 29 | B30: 45883 | F30: Bogotá | G30: Chico Lago | H30: Reserva 98-07 | I30: Revisión | J30: Jury Carolina Gonzalez | K30: -74.044046 | L30: 4.6814288 | M30: Trade Center Bog | N30: Bajo | O30: Calle 93 Bog | P30: Bajo | R30: Torre Cien Bog | S30: Alto | U30: Chico 100 Con 11 Bog | V30: Alto | AD30: =COUNTA(M30,O30,R30,U30,X30,AA30) -> 4 | AE30: =+HYPERLINK("https://www.google.com/maps?q=" & SUBSTITUTE(L30, ",", ".") & "," & SUBSTITUTE(K30, ",", "."),"Ver en mapa") -> Ver en mapa
A31: 30 | B31: 45883 | F31: Bogotá | G31: Toberin | H31: Calle 170 | I31: Revisión | J31: Leonard Castañeda | K31: -74.043254 | L31: 4.7504616 | M31: Toberin Centro Bog | N31: Bajo | AD31: =COUNTA(M31,O31,R31,U31,X31,AA31) -> 1 | AE31: =+HYPERLINK("https://www.google.com/maps?q=" & SUBSTITUTE(L31, ",", ".") & "," & SUBSTITUTE(K31, ",", "."),"Ver en mapa") -> Ver en mapa
A32: 31 | B32: 45883 | F32: Bogotá | G32: Toberin | H32: Toberin 168 | I32: Revisión | J32: Leonard Castañeda | K32: -74.042481 | L32: 4.7483631 | M32: Toberin Centro Bog | N32: Bajo | O32: Calle 166 Bog | P32: Bajo | AD32: =COUNTA(M32,O32,R32,U32,X32,AA32) -> 2 | AE32: =+HYPERLINK("https://www.google.com/maps?q=" & SUBSTITUTE(#REF!, ",", ".") & "," & SUBSTITUTE(L32, ",", "."),"Ver en mapa") -> #REF!
A33: 74 | B33: 45979 | F33: Medellin | G33: El Poblado | H33: Parque Villas | I33: Entregado | J33: Valentina Valencia Marin | K33: -75.568102 | L33: 6.2096305 | M33: Rose Poblado (Mde) | N33: Alto | AD33: =COUNTA(M33,O33,R33,U33,X33,AA33) -> 1 | AE33: =+HYPERLINK("https://www.google.com/maps?q=" & SUBSTITUTE(L33, ",", ".") & "," & SUBSTITUTE(K33, ",", "."),"Ver en mapa") -> Ver en mapa
AD34: =COUNTA(M34,O34,R34,U34,X34,AA34) -> 0 | AE34: =+HYPERLINK("https://www.google.com/maps?q=" & SUBSTITUTE(L34, ",", ".") & "," & SUBSTITUTE(K34, ",", "."),"Ver en mapa") -> Ver en mapa
A35: 33 | B35: 45896 | F35: Bogotá | G35: Los Cedros | H35: Pradia 134 | I35: Entregado | J35: Maria Alejandra Garcia | K35: -74.048486 | L35: 4.7202683 | M35: Contador (Bog) | N35: Medio | AD35: =COUNTA(M35,O35,R35,U35,X35,AA35) -> 1 | AE35: =+HYPERLINK("https://www.google.com/maps?q=" & SUBSTITUTE(L35, ",", ".") & "," & SUBSTITUTE(K35, ",", "."),"Ver en mapa") -> Ver en mapa
A36: 34 | B36: 45896 | F36: Bogotá | G36: Castilla | H36: Alsacia 78 | I36: Entregado | J36: Lina María Díaz | K36: -74.141005 | L36: 4.639407 | M36: Barrio Bavaria Bog | N36: Alto | AD36: =COUNTA(M36,O36,R36,U36,X36,AA36) -> 1 | AE36: =+HYPERLINK("https://www.google.com/maps?q=" & SUBSTITUTE(L36, ",", ".") & "," & SUBSTITUTE(K36, ",", "."),"Ver en mapa") -> Ver en mapa
A37: 35 | B37: 45897 | F37: Bogotá | G37: Pardo Rubio | H37: 7 Estorias | I37: Entregado | J37: Jury Carolina Gonzalez | K37: -74.062198 | L37: 4.641961 | M37: Defensoria (Bog) | N37: Alto | AD37: =COUNTA(M37,O37,R37,U37,X37,AA37) -> 1 | AE37: =+HYPERLINK("https://www.google.com/maps?q=" & SUBSTITUTE(L37, ",", ".") & "," & SUBSTITUTE(K37, ",", "."),"Ver en mapa") -> Ver en mapa
A38: 36 | B38: 45897 | F38: Bogotá | G38: Suba | H38: El Pino | I38: Entregado | J38: Carlos Bolaños | K38: -74.094154 | L38: 4.750085 | M38: Suba 103 Bog | N38: Bajo | O38: Imperial Bog | P38: Alto | AD38: =COUNTA(M38,O38,R38,U38,X38,AA38) -> 2 | AE38: =+HYPERLINK("https://www.google.com/maps?q=" & SUBSTITUTE(L38, ",", ".") & "," & SUBSTITUTE(K38, ",", "."),"Ver en mapa") -> Ver en mapa
A39: 37 | B39: 45897 | F39: Bogotá | G39: Suba | H39: Suba 92 | I39: Entregado | J39: Carlos Bolaños | K39: -74.084973 | L39: 4.7409118 | M39: Plaza Suba Bog | N39: Alto | AD39: =COUNTA(M39,O39,R39,U39,X39,AA39) -> 1 | AE39: =+HYPERLINK("https://www.google.com/maps?q=" & SUBSTITUTE(L39, ",", ".") & "," & SUBSTITUTE(K39, ",", "."),"Ver en mapa") -> Ver en mapa
A40: 38 | B40: 45903 | F40: Bogotá | G40: Restrepo | H40: La Fragua 17 | I40: Entregado | J40: Lina María Díaz | K40: -74.109838 | L40: 4.5963158 | M40: La Fragua (Bog) | N40: Alto | AD40: =COUNTA(M40,O40,R40,U40,X40,AA40) -> 1 | AE40: =+HYPERLINK("https://www.google.com/maps?q=" & SUBSTITUTE(L40, ",", ".") & "," & SUBSTITUTE(K40, ",", "."),"Ver en mapa") -> Ver en mapa
...

Sheet ISO
A1: ISO | B1: FECHA RECEPCIÓN | C1: FECHA DE ENVÍO ISO | D1: DÍAS DE ENVÍO | E1: PRACTICANTE | F1: MEDIO (TEAMS/ CORREO) | G1: MS (SI O NO) | H1: ESTADO | I1: NOMBRE | J1: CIUDAD | K1: ESPECIALISTA | L1: LONGITUD | M1: LATITUD | N1: COMENTARIOS
A2: 1 | B2: 46029 | C2: 46030 | D2: =C2-B2 -> 1 | E2: Isabela | F2: Correo | G2: No | H2: Entregado | I2: Data 20 | J2: Bogotá | K2: Laura Valentina Avila Gutierrez | L2: -74.113164 | M2: 4.6450103
A3: 2 | B3: 46029 | C3: 46030 | D3: =C3-B3 -> 1 | E3: Isabela | F3: Correo | G3: No | H3: Entregado | I3: Esquina Alpes Pereira | J3: Pereira | K3: Leidy Viviana Mejia | L3: -75.686793 | M3: 4.8082322
A4: 3 | B4: 46029 | C4: 46036 | D4: =C4-B4 -> 7 | E4: Isabela | F4: Correo | G4: No | H4: Entregado | I4: Portal Norte | J4: Bogotá | K4: Leidy Viviana Mejia | L4: -74.045715 | M4: 4.7545843 | N4: Se estaba tomando la decisión de la manera en la que se realizarían dichas isócronas en TM
A5: 4 | B5: 46029 | C5: 46036 | D5: =C5-B5 -> 7 | E5: Isabela | F5: Correo | G5: No | H5: Entregado | I5: Portal Suba | J5: Bogotá | K5: Leidy Viviana Mejia | L5: -74.096896 | M5: 4.7465918 | N5: Se estaba tomando la decisión de la manera en la que se realizarían dichas isócronas en TM
A6: 5 | B6: 46029 | C6: 46036 | D6: =C6-B6 -> 7 | E6: Isabela | F6: Correo | G6: No | H6: Entregado | I6: Estación Heroes | J6: Bogotá | K6: Leidy Viviana Mejia | L6: -74.060929 | M6: 4.6651828 | N6: Se estaba tomando la decisión de la manera en la que se realizarían dichas isócronas en TM
A7: 6 | B7: 46029 | C7: 46036 | D7: =C7-B7 -> 7 | E7: Isabela | F7: Correo | G7: No | H7: Entregado | I7: Portal Dorado | J7: Bogotá | K7: Leidy Viviana Mejia | L7: -74.121182 | M7: 4.6812815 | N7: Se estaba tomando la decisión de la manera en la que se realizarían dichas isócronas en TM
A8: 7 | B8: 46030 | C8: 46031 | D8: =C8-B8 -> 1 | E8: Isabela | F8: Correo | G8: No | H8: Entregado | I8: La Gaitana | J8: Bogotá | K8: Alejandra Rojas Romero | L8: -74.108917 | M8: 4.742889
A9: 8 | B9: 46030 | C9: 46035 | D9: =C9-B9 -> 5 | E9: Isabela | F9: Correo | G9: No | H9: Entregado | I9: Global Andino | J9: Bogotá | K9: Jenny Paola Acuña Rojas | L9: -74.052512 | M9: 4.6659551
A10: 9 | B10: 46030 | E10: Isabela | F10: Correo | G10: No | H10: Revisión | I10: Catilla el Amparo | J10: Bogotá | K10: Laura Valentina Avila Gutierrez | L10: -74.062234 | M10: 4.6825472
A11: 10 | B11: 46030 | C11: 46031 | D11: =C11-B11 -> 1 | E11: Isabela | F11: Correo | G11: No | H11: Entregado | I11: Hospital Militar | J11: Bogotá | K11: Laura Valentina Avila Gutierrez | L11: -74.062234 | M11: 4.6825472
A12: 11 | B12: 46030 | C12: 46031 | D12: =C12-B12 -> 1 | E12: Isabela | F12: Correo | G12: No | H12: Entregado | I12: Lourdes 13 | J12: Bogotá | K12: Laura Valentina Avila Gutierrez | L12: -74.062234 | M12: 4.6825472
A13: 12 | B13: 46030 | C13: 46031 | D13: =C13-B13 -> 1 | E13: Isabela | F13: Correo | G13: No | H13: Entregado | I13: San Martin 7 | J13: Bogotá | K13: Laura Valentina Avila Gutierrez | L13: -74.062234 | M13: 4.6825472
A14: 13 | B14: 46031 | C14: 46041 | D14: =C14-B14 -> 10 | E14: Isabela | F14: Correo | G14: Si | H14: Entregado | I14: Chile 9 | J14: Bogotá | K14: Leidy Viviana Mejia | L14: -74.056575 | M14: 4.6558223 | N14: Se encontraba en espera por Estudio de Origen Destino
A15: 14 | B15: 46035 | C15: 46038 | D15: =C15-B15 -> 3 | E15: Isabela | F15: Teams | G15: No | H15: Entregado | I15: EDS Abadía | J15: Bogotá | K15: Alejandra Rojas Romero | L15: -74.029326 | M15: 4.7112117
A16: 15 | B16: 46035 | C16: 46035 | D16: =C16-B16 -> 0 | E16: Isabela | F16: Teams | G16: No | H16: Entregado | I16: Chicó Norte | J16: Bogotá | K16: Jenny Paola Acuña Rojas | L16: -74.045212 | M16: 4.678612
A17: 16 | B17: 46035 | C17: 46035 | D17: =C17-B17 -> 0 | E17: Isabela | F17: Teams | G17: No | H17: Entregado | I17: Muequetá | J17: Bogotá | K17: Jenny Paola Acuña Rojas | L17: -74.082894 | M17: 4.6491558
A18: 17 | B18: 46035 | C18: 46035 | D18: =C18-B18 -> 0 | E18: Isabela | F18: Teams | G18: Si | H18: Entregado | I18: Jardín Norte 130 | J18: Bogotá | K18: Carlos Bolaños Díaz | L18: -74.068682 | M18: 4.7207878
A19: 18 | B19: 46035 | C19: 46035 | D19: =C19-B19 -> 0 | E19: Isabela | F19: Teams | G19: No | H19: Entregado | I19: Occidente | J19: Bogotá | K19: Laura Valentina Avila Gutierrez | L19: -74.135358 | M19: 4.6290376
A20: 19 | B20: 46035 | C20: 46036 | D20: =C20-B20 -> 1 | E20: Isabela | F20: Teams | G20: No | H20: Entregado | I20: Mazuren 150 | J20: Bogotá | K20: Carlos Bolaños Díaz | L20: -74.050222 | M20: 4.7316759
A21: 20 | B21: 46035 | C21: 46036 | D21: =C21-B21 -> 1 | E21: Isabela | F21: Teams | G21: No | H21: Entregado | I21: Oxxo Calle 138 | J21: Bogotá | K21: Carlos Bolaños Díaz | L21: -74.055401 | M21: 4.7250056
A22: 21 | B22: 46035 | C22: 46036 | D22: =C22-B22 -> 1 | E22: Isabela | F22: Teams | G22: No | H22: Entregado | I22: Torre Azul | J22: Bogotá | K22: Laura Valentina Avila Gutierrez | L22: -74.047446 | M22: 4.6835835
A23: 22 | B23: 46035 | C23: 46036 | D23: =C23-B23 -> 1 | E23: Isabela | F23: Teams | G23: No | H23: Entregado | I23: Llarco 116 | J23: Bogotá | K23: Martha Lopez | L23: -74.069417 | M23: 4.6986397
A24: 23 | B24: 46035 | C24: 46036 | D24: =C24-B24 -> 1 | E24: Isabela | F24: Teams | G24: No | H24: Entregado | I24: Zentia 125 | J24: Bogotá | K24: Martha Lopez | L24: -74.053334 | M24: 4.7052032
A25: 24 | B25: 46035 | C25: 46036 | D25: =C25-B25 -> 1 | E25: Isabela | F25: Teams | G25: No | H25: Entregado | I25: La insignia 122 | J25: Bogotá | K25: Martha Lopez | L25: -74.046884 | M25: 4.7012203
A26: 25 | B26: 46035 | C26: 46036 | D26: =C26-B26 -> 1 | E26: Isabela | F26: Teams | G26: No | H26: Entregado | I26: Delivery 119 | J26: Bogotá | K26: Martha Lopez | L26: -74.037261 | M26: 4.6982852
... A51: 50 | B51: 46043 | C51: 46043 | D51: =C51-B51 -> 0 | E51: Isabela | F51: Teams | G51: No | H51: Entregado | I51: Malecon II | J51: Barranquilla | K51: Jaime Rodrigo Gutierrez Perez | L51: -74.792927 | M51: 11.020192
A52: 51 | B52: 46043 | C52: 46050 | D52: =C52-B52 -> 7 | E52: Isabela | F52: Teams | G52: No | H52: Entregado | I52: Bodega Quintal | J52: Barranquilla | K52: Jaime Rodrigo Gutierrez Perez | L52: -74.795078 | M52: 11.021694 | N52: Esta me la pidió Jaime, pero luego Leidy me la pidió nuevamente y se le envió el 28/01
A53: 52 | B53: 46043 | C53: 46044 | D53: =C53-B53 -> 1 | E53: Isabela | F53: Teams | G53: No | H53: Entregado | I53: Academia 24 | J53: Bogotá | K53: Laura Valentina Avila Gutierrez | L53: -74.122667 | M53: 4.6689714
A54: 53 | B54: 46043 | C54: 46045 | D54: =C54-B54 -> 2 | E54: Isabela | F54: Teams | G54: No | H54: Entregado | I54: Malecon 72 | J54: Barranquilla | K54: Jaime Rodrigo Gutierrez Perez | L54: -74.785153 | M54: 11.012234
A55: 54 | B55: 46043 | C55: 46043 | D55: =C55-B55 -> 0 | E55: Laura | F55: Teams | G55: Si | H55: Entregado | I55: Quinta Real 40 | J55: Bogotá | K55: Lina María Díaz | L55: -74.09069 | M55: 4.6325044
A56: 55 | B56: 46043 | C56: 46043 | D56: =C56-B56 -> 0 | E56: Laura | F56: Correo | G56: No | H56: Entregado | I56: Ortezal 44 | J56: Bogotá | K56: Lina María Díaz | L56: -74.099507 | M56: 4.6291255
A57: 56 | B57: 46043 | C57: 46044 | D57: =C57-B57 -> 1 | E57: Laura | F57: Correo | G57: Si | H57: Entregado | I57: Black 24 | J57: Bogotá | K57: Lina María Díaz | L57: -74.093821 | M57: 4.6325199
A58: 57 | B58: 46043 | C58: 46044 | D58: =C58-B58 -> 1 | E58: Laura | F58: Teams | G58: No | H58: Entregado | I58: Metro estación Niquia | J58: Medellín | K58: Valencia Marin Valentina | L58: -75.54407 | M58: 6.33781
A59: 58 | B59: 46043 | C59: 46044 | D59: =C59-B59 -> 1 | E59: Isabela | F59: Correo | G59: Si | H59: Entregado | I59: Americas Grafiti | J59: Bogotá | K59: Jaime Rodrigo Gutierrez Perez | L59: -74.116269 | M59: 4.6277725
A60: 59 | B60: 46043 | C60: 46044 | D60: =C60-B60 -> 1 | E60: Laura | F60: Correo | G60: No | H60: Entregado | I60: Plaza Zuca | J60: Cota | K60: Valencia Marin Valentina | L60: -74.15189 | M60: 4.7549167
A61: 61 | B61: 46043 | C61: 46048 | D61: =C61-B61 -> 5 | E61: Laura | F61: Correo | G61: No | H61: Entregado | I61: Metro estación San Antonio | J61: Medellín | K61: Valencia Marin Valentina | L61: -75.569874 | M61: 6.2472344
A62: 60 | B62: 46044 | C62: 46045 | D62: =C62-B62 -> 1 | E62: Isabela | F62: Correo | G62: No | H62: Entregado | I62: Zona 53 | J62: Bogotá | K62: Jenny Paola Acuña Rojas | L62: -74.076707 | M62: 4.6424582
A63: 62 | B63: 46045 | C63: 46048 | D63: =C63-B63 -> 3 | E63: Laura | F63: Correo | G63: No | H63: Entregado | I63: Oxxo Barbara 116 | J63: Bogotá | K63: Martha Lopez | L63: -74.042805 | M63: 4.6978625
A64: 63 | B64: 46045 | C64: 46048 | D64: =C64-B64 -> 3 | E64: Isabela | F64: Correo | G64: Si | H64: Entregado | I64: Parque Chapinero | J64: Bogotá | K64: Laura Valentina Avila Gutierrez | L64: -74.060626 | M64: 4.6483148
...

Sheet Tiendas operando 
A1: CR | B1: Tienda | C1: UPZ
A2: 50WHX | B2: 140 | C2: AEROPUERTO EL DORADO | G2: Estado
A3: 505ST | B3: 724 | C3: ALAMOS | G3: Solicitado
A4: 50QK2 | B4: 1ero De Mayo | C4: AMERICAS | G4: Revisión
A5: 50VEG | B5: 72 Caracas | C5: APOGEO | G5: Entregado
A6: 50EXM | B6: 72 Castilla | C6: ARBORIZADORA
A7: 50WLE | B7: 73 Kennedy | C7: BAVARIA
A8: 50JA1 | B8: 78 Kennedy | C8: BOLIVIA | G8: Especialistas
A9: 505TQ | B9: Acacias | C9: BOSA CENTRAL | G9: Laura Valentina Avila Gutierrez
A10: 509BS | B10: Acomedica 2 | C10: BOYACA REAL | G10: Jury Carolina Gonzalez | J10: Practicantes | L10: Medio | N10: MS
A11: 502B0 | B11: Acuarela | C11: BRITALIA | G11: Alejandra Rojas Romero | J11: Juan | L11: Correo | N11: Si
A12: 50IHY | B12: Afe Refugio | C12: CALANDAIMA | G12: Cindy Torres | J12: Alisson | L12: Teams | N12: No
A13: 505DL | B13: Agustin | C13: CAPELLANIA | G13: Walter Santiago Quintero | J13: Elanie
A14: 50T5A | B14: Alameda De Unicentro | C14: CARVAJAL | G14: Andres Duque
A15: 50UPU | B15: Alamos 90 | C15: CASA BLANCA SUBA | G15: Jhoana Jaimes
A16: 50FZH | B16: Alamos Industrial | C16: CASTILLA | G16: Lina María Díaz | L16: 46031 | M16: 46041 | N16: 10 | O16: Isabela | P16: Correo | Q16: Si | R16: Entregado | S16: Chile 9 | T16: Leidy Viviana Mejia | U16: -74.056575 | V16: 4.6558223
A17: 50TWU | B17: Alamos Norte | C17: CHAPINERO | G17: Jenny Paola Acuña Rojas | L17: 46035 | M17: 46035 | N17: 0 | O17: Isabela | P17: Teams | Q17: Si | R17: Entregado | S17: Jardín Norte 130 | T17: Carlos Bolaños Díaz | U17: -74.068682 | V17: 4.7207878
A18: 50WJD | B18: Alcabama 100 | C18: CHICO LAGO | G18: Jairo Delagado Pineda | L18: 46036 | M18: 46041 | N18: 5 | O18: Isabela | P18: Correo | Q18: Si | R18: Entregado | S18: Centro 93 | T18: Laura Valentina Avila Gutierrez | U18: -74.051567 | V18: 4.6771437
A19: 50IOP | B19: Alcala | C19: CIUDAD JARDIN | G19: Leidy Viviana Mejia | L19: 46036 | M19: 46042 | N19: 6 | O19: Isabela | P19: Correo | Q19: Si | R19: Entregado | S19: Graund Cl75 | T19: Laura Valentina Avila Gutierrez | U19: -74.06537 | V19: 4.6655748
A20: 503Z7 | B20: Aldea Comercial | C20: CIUDAD MONTES | G20: Laura Vecino Marrugo | L20: 46037 | M20: 46041 | N20: 4 | O20: Isabela | P20: Correo | Q20: Si | R20: Entregado | S20: Urbano 61 | T20: Laura Valentina Avila Gutierrez | U20: -74.063745 | V20: 4.6477057
A21: 50K6C | B21: Alfonso Lopez | C21: CIUDAD SALITRE OCCIDENTAL | G21: Maria Alejandra Ardila Sanchez | L21: 46037 | M21: 46038 | N21: 1 | O21: Isabela | P21: Correo | Q21: Si | R21: Entregado | S21: Cabañas 63 | T21: Jenny Paola Acuña Rojas | U21: -74.065162 | V21: 4.6495882
A22: 50HZJ | B22: Almacentro | C22: CIUDAD SALITRE ORIENTAL | G22: Paola Cardona | L22: 46037 | M22: 46038 | N22: 1 | O22: Isabela | P22: Correo | Q22: Si | R22: Entregado | S22: Centenario M45 | T22: Jenny Paola Acuña Rojas | U22: -74.072321 | V22: 4.6335002
A23: 50L8W | B23: Alonso Calle 19 | C23: COUNTRY CLUB | G23: Martha Lopez | L23: 46038 | M23: 46043 | N23: 5 | O23: Isabela | P23: Correo | Q23: Si | R23: Entregado | S23: Metro I | T23: Laura Valentina Avila Gutierrez | U23: -74.061025 | V23: 4.6613596
A24: 50SKG | B24: Alsacia | C24: DOCE DE OCTUBRE | G24: Carlos Bolaños Díaz | L24: 46042 | M24: 46045 | N24: 3 | O24: Isabela | P24: Correo | Q24: Si | R24: Entregado | S24: San Cristobal | T24: Leidy Viviana Mejia | U24: -74.027658 | V24: 4.7383551
A25: 50P88 | B25: Alta Suiza | C25: EL PRADO | G25: Jaime Rodrigo Gutierrez | L25: 46043 | M25: 46043 | N25: 0 | O25: Laura | P25: Teams | Q25: Si | R25: Entregado | S25: Quinta Real 40 | T25: Lina María Díaz | U25: -74.09069 | V25: 4.6325044
A26: 50PT8 | B26: Altavista | C26: EL REFUGIO | L26: 46043 | M26: 46044 | N26: 1 | O26: Laura | P26: Correo | Q26: Si | R26: Entregado | S26: Black 24 | T26: Lina María Díaz | U26: -74.093821 | V26: 4.6325199
A27: 505N0 | B27: Alto Prado 49C | C27: EL RINCON | G27: Riesgo | L27: 46043 | M27: 46044 | N27: 1 | O27: Isabela | P27: Correo | Q27: Si | R27: Entregado | S27: Americas Grafiti | T27: Jaime Rodrigo Gutierrez Perez | U27: -74.116269 | V27: 4.6277725
A28: 50L9T | B28: Alto Prado 76 | C28: ENGATIVA | G28: Alto | L28: 46044 | M28: 46045 | N28: 1 | O28: Isabela | P28: Correo | Q28: Si | R28: Entregado | S28: Zona 53 | T28: Jenny Paola Acuña Rojas | U28: -74.076707 | V28: 4.6424582
A29: 50YHD | B29: Altos De Cabecera 2 | C29: FONTIBON | G29: Medio | L29: 46045 | M29: 46048 | N29: 3 | O29: Isabela | P29: Correo | Q29: Si | R29: Entregado | S29: Parque Chapinero | T29: Laura Valentina Avila Gutierrez | U29: -74.060626 | V29: 4.6483148
A30: 50Y4E | B30: Altos Del Ciclista | C30: GALERIAS | G30: Bajo | L30: 46048 | M30: 46049 | N30: 1 | O30: Isabela | P30: Correo | Q30: Si | R30: Entregado | S30: Indigo 93 | T30: Jaime Rodrigo Gutierrez Perez | U30: -74.049669 | V30: 4.6780024
A31: 501YH | B31: America Occidental | C31: GARCES NAVAS | L31: 46048 | M31: 46050 | N31: 2 | O31: Isabela | P31: Correo | Q31: Si | R31: Entregado | S31: 72 Kuepa | T31: Jaime Rodrigo Gutierrez Perez | U31: -74.060628 | V31: 4.6587166
A32: 50417 | B32: Américas 72 | C32: GRAN BRITALIA | L32: 46050 | M32: 46051 | N32: 1 | O32: Laura | P32: Teams | Q32: Si | R32: Entregado | S32: Torre C | T32: Lina María Díaz | U32: -74.07009 | V32: 4.6104702
A33: 50VOZ | B33: Américas Boyacá | C33: GRANJAS DE TECHO | L33: 46050 | M33: 46051 | N33: 1 | O33: Laura | P33: Teams | Q33: Si | R33: Entregado | S33: Oxxo Registraduría Usaquén | T33: Martha Lopez | U33: -74.030152 | V33: 4.698664
A34: 50IP7 | B34: Anillo Vial | C34: ISMAEL PERDOMO | L34: 46051 | M34: 46051 | N34: 0 | O34: Laura | P34: Teams | Q34: Si | R34: Entregado | S34: Unindustriales | T34: Jenny Paola Acuña Rojas | U34: -74.070584 | V34: 4.6381721
A35: 502XT | B35: Antigua | C35: JARDIN BOTANICO | L35: 46055 | M35: 46056 | N35: 1 | O35: Isabela | P35: Correo | Q35: Si | R35: Entregado | S35: Centro 93 | T35: Jaime Rodrigo Gutierrez Perez | U35: -74.051643 | V35: 4.6769549
A36: 50OMJ | B36: Aquazul | C36: KENNEDY CENTRAL | L36: 46055 | M36: 46056 | N36: 1 | O36: Isabela | P36: Correo | Q36: Si | R36: Entregado | S36: Occi-plus | T36: Jaime Rodrigo Gutierrez Perez | U36: -74.135365 | V36: 4.6291257
A37: 50CV4 | B37: Arbolatta Mall | C37: LA ALHAMBRA | L37: 46055 | M37: 46057 | N37: 2 | O37: Isabela | P37: Correo | Q37: Si | R37: Entregado | S37: Septima setenta | T37: Jaime Rodrigo Gutierrez Perez | U37: -74.056607 | V37: 4.6530127
A38: 50R0P | B38: Arrayanes | C38: LA CANDELARIA | L38: 46055 | M38: 46057 | N38: 2 | O38: Isabela | P38: Correo | Q38: Si | R38: Entregado | S38: Centro 93 parking | T38: Jaime Rodrigo Gutierrez Perez | U38: -74.050829 | V38: 4.6773687
A39: 50B6R | B39: Arrecife | C39: LA ESMERALDA | L39: 46055 | M39: 46057 | N39: 2 | O39: Isabela | P39: Correo | Q39: Si | R39: Entregado | S39: Kennedy Cade | T39: Jaime Rodrigo Gutierrez Perez | U39: -74.153979 | V39: 4.6232006
A40: 50ZFN | B40: Asturias | C40: LA FLORESTA | L40: 46055 | M40: 46058 | N40: 3 | O40: Isabela | P40: Correo | Q40: Si | R40: Entregado | S40: Lago 82-15 | T40: Jaime Rodrigo Gutierrez Perez | U40: -74.056672 | V40: 4.6674207
...
